Workbook

Sheet Data
A1: Bundles | E1: Coach | F1: Rink | H1: Group | I1: Level | J1: Coach
A2: Type | B2: Hours | C2: Fees | D2: Cash | E2: Ahmed | F2: ELMalahy | H2: Kids | I2: Kids | J2: Ahmed /clara
A3: On-Ice Bronze | B3: 4 | C3: 1500 | D3: Instapay | E3: Esraa | F3: SunCity | H3: Pre-bronze | I3: Pre-Alpha | J3: Eman
A4: On-Ice Silver | B4: 8 | C4: 2800 | E4: Maryam | F4: Genana | I4: Alpha
A5: On-Ice Gold | B5: 12 | C5: 4000 | D5: 3600 | E5: Hajar | F5: Both | I5: Beta | J5: Hajar
E6: Clara | H6: Bronze | I6: Gamma
A7: Off- Ice Bronze | B7: 4 | C7: 800 | D7: 600 | E7: Eman | I7: Delta | J7: Esraa
A8: Off- Ice Silver | B8: 8 | C8: 1400 | D8: 1000 | E8: Sally | I8: Freestyle 1
A9: Off- Ice Gold | B9: 12 | C9: 2000 | D9: 1200 | E9: Coach | H9: Silver | I9: Freestyle 2 | J9: Clara
I10: Freestyle 3 | J10: Maryam
A11: Private | B11: 1 | C11: 600 | I11: Freestyle 4
A12: Per Session | B12: 1 | C12: 400
H13: Gold | I13: Freestyle 5 | J13: Ahmed
A14: Off-On Ice Bronze | B14: 8-4 | C14: 3600 | I14: Freestyle 6
A15: Off-On Ice Silver | B15: 12-4 | C15: 4500 | D15: 3600 | I15: Freestyle 7
A16: Off-On Ice Gold | B16: 12-8 | C16: 5200 | D16: 4200 | I16: Freestyle 8
I17: Freestyle 9
A18: 45693 | B18: 1 | C18: 500 | I18: Freestyle 10
B19: 4 | C19: 1800
B20: 8 | C20: 3600
B21: 12 | C21: 5200
A24: Levels | B24: Kids | D24: Pre-Alpha : Beta | F24: Gamma : FS1 | H24: FS2: FS4 | J24: FS5 : FS10
A25: Level's Name | B25: Kids | D25: Pre-bronze | F25: Bronze | H25: Silver | J25: Gold
B26: Kids 1 | C26: Kids 2 | D26: Pre-bronze 1 | E26: Pre-bronze 2 | F26: Bronze 1 | G26: Bronze 2 | H26: Silver 1 | I26: Silver 2 | J26: Gold | K26: Elite
D27: Pre-Alpha | E27: Beta | F27: Gamma : Delta | G27: FS1 | H27: FS2:FS3 | I27: FS4
A28: Coach | B28: Saad | C28: Clara | D28: Eman | E28: Esraa | F28: Esraa | G28: Hajer | H28: Maryem / Clara | I28: Saad / Maryem | J28: saad

Sheet Traniees Name & Package
A1: Membership N | B1: Name | F1: Level
C2: Bundle | D2: Price | E2: Coach
A3: 1 | B3: Ahmed saad | D3: 0 | E3: Coach | F3: Freestyle 10
A4: 2 | B4: Shaimaa El-Adl | D4: 0 | E4: Ahmed
A5: 3 | B5: Esraa Nabil | D5: 0 | E5: Coach
A6: 4 | B6: Maryam Mohamed | D6: 0 | E6: Ahmed
A7: 5 | B7: Hajar Munir | D7: 0 | E7: Coach
A8: 6 | B8: Clara Amgad | D8: 0 | E8: Coach
A9: 7 | B9: Eman moustafa | D9: 0 | E9: Coach
A10: 8 | B10: Sally Elziady | D10: 0 | E10: Ahmed
A11: 9 | B11: Salma Nagy | D11: 0 | E11: Ahmed
A12: 10 | B12: Aya khaled | D12: 0 | E12: Ahmed
A13: 11 | B13: Ganna Elkhayat | D13: 0 | E13: Ahmed
A14: 12 | B14: Charlotte Nash | D14: 0 | E14: Ahmed
A15: 13 | B15: Heddia Motaz Ahmed Samy | D15: 0 | E15: Ahmed
A16: 14 | B16: Maggie Mostafa Shams | D16: 0 | E16: Ahmed
A17: 15 | B17: Mariam Amr Arafa | D17: 0 | E17: Ahmed
A18: 16 | B18: Emma Fadi Fouad | D18: 0 | E18: Ahmed
A19: 17 | B19: Hallah Mahmoud Taher | D19: 0 | E19: Ahmed
A20: 18 | B20: Injy Ashraf | D20: 0 | E20: Hajar
A21: 19 | B21: Fatima Elhawary | D21: 0 | E21: Hajar
... A41: 39 | B41: Elina | D41: 0 | E41: Ahmed
A42: 40 | B42: Maya Mohamed | E42: Ahmed
A43: 41 | B43: Caroline | D43: 0 | E43: Hajar
A44: 42 | B44: Fayrouz Mohamed Abd elmoaty | D44: 0 | E44: Ahmed
A45: 43 | B45: Fayrouz Mohamed Ibrahim | D45: 0 | E45: Esraa
A46: 44 | B46: Kenzy | D46: 0 | E46: Maryam
A47: 45 | B47: Habiba Eldemerdash | D47: 0 | E47: Maryam
A48: 46 | B48: Sara Ibrahim | D48: 0 | E48: Ahmed
A49: 47 | B49: Celine Sameh | D49: 0 | E49: Eman
A50: 48 | B50: Kenzy Khaled | D50: 0 | E50: Ahmed
A51: 49 | B51: Lara Mostafa | D51: 0 | E51: Esraa
A52: 50 | B52: Retaj Mohamed | D52: 0 | E52: Clara
A53: 51 | B53: Lojain Ahmed Mohamed | D53: 0 | E53: Eman
A54: 52 | B54: Yasmine Mahmoud | D54: 0 | E54: Maryam
... A66: 64 | B66: Somaia Samer | D66: 0 | E66: Esraa
A67: 65 | B67: Lobna Yasser | E67: Maryam
A68: 66 | B68: Noura Wael | E68: Esraa
A69: 67 | B69: Aliaa Ahmed | E69: Ahmed
A70: 68 | B70: Shahd Khaled | E70: Eman
...

Sheet Off-Ice Attendence
A1: 45962 | B1: 45963 | C1: 45964 | D1: 45965 | E1: 45966 | F1: 45967 | G1: 45968 | H1: 45969 | I1: 45970 | J1: 45971 | K1: 45972 | L1: 45973 | M1: 45974 | N1: 45975 | O1: 45976 | P1: 45977 | Q1: 45978 | R1: 45979 | S1: 45980 | T1: 45981 | U1: 45982 | V1: 45983 | W1: 45984 | X1: 45985 | Y1: 45986 | Z1: 45987 | AA1: 45988 | AB1: 45990 | AC1: 45991
H2: Lily Islam | O2: Mostafa Mohamed Hassan | S2: Retal Mohaamed | Y2: Charlotte Nash | AB2: Noura Wael
H3: Charlotte Nash | O3: Noura Wael | S3: Sara Ibrahim | Y3: Heddia Motaz Ahmed Samy | AB3: Mariam Ashraf
H4: Nouran Mohsen | O4: Zeina mohamed salah | S4: Ganna Elkhayat
H5: Malak Ehab | O5: Youmna Wael | S5: Reem Abdelhamid
H6: Aya khaled | O6: Aya khaled | S6: Fayrouz Mohamed Abd elmoaty
H7: Arwa Sherif Ibrahim | S7: Kenzy Khaled

Sheet November 2025 Attendence
A1: 45962 | D1: 45963 | G1: 45964 | J1: 45965 | M1: 45966 | P1: 45967 | S1: 45969 | V1: 45970 | Y1: 45971 | AB1: 45972 | AE1: 45973 | AH1: 45974 | AK1: 45976 | AN1: 45977 | AQ1: 45978 | AT1: 45979 | AW1: 45980 | AZ1: 45981 | BC1: 45983 | BF1: 45984 | BI1: 45985 | BL1: 45986 | BO1: 45987 | BR1: 45988 | BU1: 45990 | BX1: 45991
A2: Off-ice | B2: On-ice | C2: Coach | D2: Off-ice | E2: On-ice | F2: Coach | G2: Off-ice | H2: On-ice | I2: Coach | J2: Off-ice | K2: On-ice | L2: Coach | M2: Off-ice | N2: On-ice | O2: Coach | P2: Off-ice | Q2: On-ice | R2: Coach | S2: Off-ice | T2: On-ice | U2: Coach | V2: Off-ice | W2: On-ice | Y2: Off-ice | Z2: On-ice | AA2: Coach | AB2: Off-ice | AC2: On-ice | AD2: Coach | AE2: Off-ice | AF2: On-ice | AG2: Coach | AH2: Off-ice | AI2: On-ice | AJ2: Coach | AK2: Off-ice | AL2: On-ice | AM2: Coach | AN2: Off-ice | AO2: On-ice | AP2: Coach | AQ2: Off-ice | AR2: On-ice | AS2: Coach | AT2: Off-ice | AU2: On-ice | AV2: Coach | AW2: Off-ice | AX2: On-ice | AY2: Coach | AZ2: Off-ice | BA2: On-ice | BB2: Coach | BC2: Off-ice | BD2: On-ice | BE2: Coach | BF2: Off-ice | BG2: On-ice | BH2: Coach | BI2: Off-ice | BJ2: On-ice | BK2: Coach | BL2: Off-ice | BM2: On-ice | BN2: Coach | BO2: Off-ice | BP2: On-ice | BQ2: Coach | BR2: Off-ice | BS2: On-ice | BT2: Coach | BU2: Off-ice | BV2: On-ice | BW2: Coach | BX2: Off-ice | BY2: On-ice | BZ2: Coach
B3: Esraa Nabil | C3: Coach | E3: Hajar Munir | F3: Coach | H3: Hajar Munir | I3: Coach | K3: Clara Amgad | L3: Coach | N3: Ahmed saad | O3: Coach | T3: Ahmed saad | U3: Coach | V3: !! | W3: Hajar Munir | X3: Coach | Z3: Ahmed saad | AA3: Coach | AB3: !! | AC3: Hajar Munir | AD3: Coach | AF3: Ahmed saad | AG3: Coach | AL3: Ahmed saad | AM3: Coach | AO3: Ahmed saad | AP3: Coach | AR3: Ahmed saad | AS3: Coach | AX3: Ahmed saad | AY3: Coach | BA3: Ahmed saad | BB3: Coach | BD3: Ahmed saad | BE3: Coach | BG3: Ahmed saad | BH3: Coach | BJ3: Ahmed saad | BK3: Coach | BM3: Ahmed saad | BN3: Coach | BP3: Ahmed saad | BQ3: Coach | BS3: Ahmed saad | BT3: Coach | BV3: Ahmed saad | BW3: Coach | BY3: Ahmed saad | BZ3: Coach
B4: Clara Amgad | C4: Coach | E4: Injy Ashraf | F4: Hajar | H4: Maryam mohamed | I4: Coach | K4: Hanan Elsheikh | L4: Clara | N4: Esraa Nabil | O4: Coach | T4: Esraa Nabil | U4: Coach | V4: !! | W4: Caroline | X4: Hajar | Z4: Farida Atwa | AA4: Ahmed | AB4: !! | AC4: Lili Elhawary | AD4: Hajar | AF4: Esraa Nabil | AG4: Coach | AL4: Esraa Nabil | AM4: Coach | AO4: Salma Nagy | AP4: Ahmed | AR4: Hajar Munir | AS4: Coach | AX4: Esraa Nabil | AY4: Coach | BA4: Hajar Munir | BB4: Coach | BD4: Esraa Nabil | BE4: Coach | BG4: Elina | BH4: Ahmed | BJ4: Ganna Elkhayat | BK4: Ahmed | BL4: !! | BM4: Maryam mohamed | BN4: Coach | BP4: Esraa Nabil | BQ4: Coach | BS4: Elina | BT4: Ahmed | BV4: Esraa Nabil | BW4: Coach | BY4: Esraa Nabil | BZ4: Coach
B5: Arwa Ahmed Abbas | C5: Clara | E5: Caroline | F5: Hajar | H5: Kenzy | I5: Maryam | N5: Eman moustafa | O5: Coach | T5: Eman moustafa | U5: Coach | V5: !! | W5: Nouran Mohsen | X5: Hajar | Z5: Reem Abdelhamid | AA5: Ahmed | AB5: !! | AC5: Fatima Elhawary | AD5: Hajar | AF5: Eman moustafa | AG5: Coach | AL5: Eman moustafa | AM5: Coach | AO5: Roza | AP5: Ahmed | AR5: Maryam mohamed | AS5: Coach | AX5: Eman moustafa | AY5: Coach | BA5: Lili Elhawary | BB5: Hajar | BD5: Eman moustafa | BE5: Coach | BG5: Salma Nagy | BH5: Ahmed | BJ5: Farida Atwa | BK5: Ahmed | BL5: !! | BM5: Tala Ahmed | BN5: Maryam | BP5: Clara Amgad | BQ5: Coach | BS5: Salma Nagy | BT5: Ahmed | BV5: Clara Amgad | BW5: Coach | BY5: Maryam mohamed | BZ5: Coach
B6: Arwa Ahmed Abbas | C6: Clara | H6: Lobna Yasser | I6: Maryam | N6: Mariam el hodeiby | O6: Eman | T6: Clara Amgad | U6: Coach | Z6: Shahd Abdelhamied | AA6: Ahmed | AF6: Maryam mohamed | AG6: Coach | AL6: Maryam mohamed | AM6: Coach | AO6: Elina | AP6: Ahmed | AR6: Nouran Mohsen | AS6: Hajar | AW6: !! | AX6: Clara Amgad | AY6: Coach | BA6: Fatima Elhawary | BB6: Hajar | BD6: Maryam mohamed | BE6: Coach | BG6: Sara Ibrahim | BH6: Ahmed | BJ6: Reem Abdelhamid | BK6: Ahmed | BL6: !! | BM6: Habiba Eldemerdash | BN6: Maryam | BP6: Eman moustafa | BQ6: Coach | BS6: Hanin Yehia | BT6: Ahmed | BV6: Eman moustafa | BW6: Coach | BX6: !! | BY6: Hajar Munir | BZ6: Coach
B7: Youmna Wael | C7: Clara | H7: Nancy Amin | I7: Maryam | N7: Mariam el hodeiby | O7: Eman | T7: Asser Haytham | U7: Eman | Z7: Ganna Elkhayat | AA7: Ahmed | AF7: Mariam el hodeiby | AG7: Eman | AK7: !! | AL7: Clara Amgad | AM7: Coach | AO7: Hanin Yehia | AP7: Ahmed | AR7: Injy Ashraf | AS7: Hajar | AX7: Nawara Yasser | AY7: Eman | BA7: Charlotte Nash | BB7: Ahmed | BD7: Clara Amgad | BE7: Coach | BJ7: Maram Khaled | BK7: Ahmed | BL7: !! | BM7: Walaa | BN7: Maryam | BP7: Nada Hany | BQ7: Esraa | BS7: Farah Magdy | BT7: Ahmed | BV7: Tala Ahmed | BW7: Esraa | BY7: Nada Hany | BZ7: Esraa
B8: Youmna Wael | C8: Clara | H8: Dina Motawea | I8: Maryam | N8: Shahd Khaled | O8: Eman | T8: Asser Haytham | U8: Eman | Z8: Noor Abdenbi | AA8: Ahmed | AF8: Mariam el hodeiby | AG8: Eman | AK8: Mostafa | AL8: Mostafa Mohamed Hassan | AM8: Esraa | AO8: Sara Ibrahim | AP8: Ahmed | AR8: Salma | AS8: Maryam | AX8: Lily Islam | AY8: Eman | BA8: Elina | BB8: Ahmed | BD8: Nada Hany | BE8: Esraa | BJ8: Emma Fadi Fouad | BK8: Ahmed | BL8: !! | BM8: Salma | BN8: Maryam | BP8: Mostafa Mohamed Hassan | BQ8: Esraa | BV8: Nada Hany | BW8: Esraa | BY8: Mona Maamoun | BZ8: Esraa
B9: Malak Hatem | C9: Clara | H9: Malika Mohamed | I9: Maryam | N9: Shahd Khaled | O9: Eman | T9: Shahd Khaled | U9: Eman | Z9: Kenzy Khaled | AA9: Ahmed | AF9: Farah El semary | AG9: Eman | AK9: Nouraa | AL9: Noura Wael | AM9: Esraa | AR9: Walaa | AS9: Maryam | AX9: Habiba Ashraf | AY9: Eman | BA9: Farida Atwa | BB9: Ahmed | BD9: Mona Maamoun | BE9: Esraa | BJ9: Fayrouz Mohamed Abd elmoaty | BK9: Ahmed | BL9: charlie | BM9: Charlotte Nash | BN9: Ahmed | BP9: Noura Wael | BQ9: Esraa | BV9: Mona Maamoun | BW9: Esraa | BX9: !! | BY9: Injy Ashraf | BZ9: Hajar
B10: Joud Mohamed | C10: Esraa | H10: Lili Elhawary | I10: Hajar | N10: Asser Haytham | O10: Eman | T10: Shahd Khaled | U10: Eman | Z10: Emma Fadi Fouad | AA10: Ahmed | AF10: Farah El semary | AG10: Eman | AL10: Sama Sherif | AM10: Esraa | AR10: Tala Ahmed | AS10: Maryam | AX10: Salma Osama | AY10: Eman | BA10: Heddia Motaz Ahmed Samy | BB10: Ahmed | BD10: Fayrouz Mohamed Ibrahim | BE10: Esraa | BJ10: Hana Tamer | BK10: Ahmed | BL10: Heddia | BM10: Heddia Motaz Ahmed Samy | BN10: Ahmed | BP10: Noura Wael | BQ10: Esraa | BV10: Mostafa Mohamed Hassan | BW10: Esraa | BX10: !! | BY10: Injy Ashraf | BZ10: Hajar
B11: Joud Mohamed | C11: Esraa | H11: Fatima Elhawary | I11: Hajar | N11: Asser Haytham | O11: Eman | T11: Lily Islam | U11: Eman | Z11: Maggie Mostafa Shams | AA11: Ahmed | AF11: Lily Islam | AG11: Eman | AL11: Shahd Elsaid | AM11: Esraa | AR11: Salma Nagy | AS11: Ahmed | AX11: Farah El semary | AY11: Eman | BD11: Fayrouz Mohamed Ibrahim | BE11: Esraa | BJ11: Farah Magdy | BK11: Ahmed | BP11: Sama Sherif | BQ11: Esraa | BV11: Mostafa Mohamed Hassan | BW11: Esraa | BX11: !! | BY11: Nouran Mohsen | BZ11: Hajar
B12: Lorina Hany | C12: Esraa | H12: Nouran Mohsen | I12: Hajar | N12: Nawara Yasser | O12: Eman | S12: Lily | T12: Lily Islam | U12: Eman | Z12: Hallah Mahmoud Taher | AA12: Ahmed | AF12: Nawara Yasser | AG12: Eman | AL12: Sara Khaled | AM12: Esraa | AR12: Farida Atwa | AS12: Ahmed | AX12: Farah El semary | AY12: Eman | BD12: Somaia Samer | BE12: Esraa | BJ12: Hajar Abdelwahab | BK12: Ahmed | BP12: Shahd Elsaid | BQ12: Esraa | BV12: Joud Mohamed | BW12: Esraa
B13: Lorina Hany | C13: Esraa | N13: Hania Hany | O13: Eman | T13: Celine Sameh | U13: Eman | AF13: Hania Hany | AG13: Eman | AL13: Leen Ghoneim | AM13: Esraa | AR13: Maram Khaled | AS13: Ahmed | AX13: Nada Hany | AY13: Esraa | BD13: Sama Sherif | BE13: Esraa | BJ13: Maggie Mostafa Shams | BK13: Ahmed | BP13: Lara Mostafa | BQ13: Esraa | BV13: Joud Mohamed | BW13: Esraa
B14: Sama Sherif | C14: Esraa | N14: Salma Osama | O14: Eman | T14: Maya stive | U14: Clara | AF14: Malika Mohamed | AG14: Maryam | AL14: Shahd Khaled | AM14: Eman | AR14: Fayrouz Mohamed Abd elmoaty | AS14: Ahmed | AX14: Mostafa Mohamed Hassan | AY14: Esraa | BD14: Shahd Elsaid | BE14: Esraa | BJ14: Hallah Mahmoud Taher | BK14: Ahmed | BP14: Lara Mostafa | BQ14: Esraa | BU14: Nouraa | BV14: Noura Wael | BW14: Esraa
B15: Sara Khaled | C15: Esraa | N15: Nada Hany | O15: Esraa | T15: Maya stive | U15: Clara | AF15: Dina Motawea | AG15: Maryam | AL15: Shahd Khaled | AM15: Eman | AR15: Noor Abdenbi | AS15: Ahmed | AX15: Mostafa Mohamed Hassan | AY15: Esraa | BD15: Shahd Elsaid | BE15: Esraa | BP15: Arwa Ahmed Abbas | BQ15: Clara | BV15: Sama Sherif | BW15: Esraa
B16: Sara Khaled | C16: Esraa | N16: Joud Mohamed | O16: Esraa | T16: Malak Hatem | U16: Clara | AF16: Tala Ahmed | AG16: Maryam | AL16: Lily Islam | AM16: Eman | AR16: Kenzy Khaled | AS16: Ahmed | AX16: Joud Mohamed | AY16: Esraa | BD16: Lara Mostafa | BE16: Esraa | BP16: Retaj Mohamed | BQ16: Clara | BV16: Sara Khaled | BW16: Esraa
B17: Mona Maamoun | C17: Esraa | N17: Laila Ahmed | O17: Esraa | T17: Hayat Walid | U17: Clara | AF17: Walaa | AG17: Maryam | AL17: Celine Sameh | AM17: Eman | AR17: Hana Tamer | AS17: Ahmed | AX17: Sama Sherif | AY17: Esraa | BD17: Leen Ghoneim | BE17: Esraa | BP17: Shahd Khaled | BQ17: Eman | BV17: Shahd Elsaid | BW17: Esraa
B18: yasmine Ahmed | C18: Esraa | N18: Lara Mostafa | O18: Esraa | T18: Anas Shaarawy | U18: Clara | AF18: Salma | AG18: Maryam | AL18: Maya Emad | AM18: Eman | AR18: Maggie Mostafa Shams | AS18: Ahmed | AX18: Sara Khaled | AY18: Esraa | BD18: Zeina mohamed salah | BE18: Esraa | BP18: Shahd Khaled | BQ18: Eman | BV18: Farah El semary | BW18: Eman
N19: Mariam Mohamed Hassan | O19: Esraa | T19: Arwa Ahmed Abbas | U19: Clara | AF19: Nada Hany | AG19: Esraa | AL19: Jana Emad | AM19: Eman | AR19: Emma Fadi Fouad | AS19: Ahmed | AX19: Shahd Elsaid | AY19: Esraa | BD19: Kenzy Khaled | BE19: Esraa | BP19: Mariam el hodeiby | BQ19: Eman | BV19: Farah El semary | BW19: Eman
N20: Zeina mohamed salah | O20: Esraa | T20: Arwa Ahmed Abbas | U20: Clara | AF20: Joud Mohamed | AG20: Esraa | AL20: Jaida Ayman badawi | AM20: Eman | AR20: Ganna Elkhayat | AS20: Ahmed | AX20: Mariam Mohamed Hassan | AY20: Esraa | BD20: Shahd Khaled | BE20: Eman | BP20: Mariam el hodeiby | BQ20: Eman | BV20: Lojain Ahmed Mohamed | BW20: Eman
N21: Kenzy Khaled | O21: Esraa | T21: Nada Hany | U21: Esraa | AF21: Joud Mohamed | AG21: Esraa | AL21: Nareman Osama | AM21: Maryam | AR21: Hajar Abdelwahab | AS21: Ahmed | AW21: !! | AX21: Arwa Ahmed Abbas | AY21: Clara | BD21: Shahd Khaled | BE21: Eman | BP21: Farah El semary | BQ21: Eman | BV21: Habiba Ashraf | BW21: Eman
N22: Maya Mohamed | O22: Esraa | T22: Mostafa Mohamed Hassan | U22: Esraa | AF22: Sama Sherif | AG22: Esraa | AL22: Yasmine Mahmoud | AM22: Maryam | AR22: Maya Mohamed | AS22: Ahmed | AW22: Retaal | AX22: Retal Mohaamed | AY22: Ahmed | BD22: Asser Haytham | BE22: Eman | BP22: Farah El semary | BQ22: Eman | BV22: Arwa Ahmed Abbas | BW22: Clara
N23: Farida Atwa | O23: Ahmed | T23: Fayrouz Mohamed Ibrahim | U23: Esraa | AF23: Laila Ahmed | AG23: Esraa | AK23: !! | AL23: Hayat Walid | AM23: Clara | AW23: Saraa | AX23: Sara Ibrahim | AY23: Ahmed | BD23: Asser Haytham | BE23: Eman | BP23: Lily Islam | BQ23: Eman | BU23: Mariaam | BV23: Mariam Ashraf | BW23: Ahmed
N24: Nadine Mostafa | O24: Ahmed | T24: Fayrouz Mohamed Ibrahim | U24: Esraa | AF24: Ganna Elkhayat | AG24: Ahmed | AK24: !! | AL24: Maya stive | AM24: Clara | AW24: Gannaa | AX24: Ganna Elkhayat | AY24: Ahmed | BD24: Lojain Ahmed Mohamed | BE24: Eman | BP24: Lily Islam | BQ24: Eman | BV24: Retal Mohaamed | BW24: Ahmed
N25: Charlotte Nash | O25: Ahmed | S25: Nouraa | T25: Noura Wael | U25: Esraa | AF25: Farida Atwa | AG25: Ahmed | AK25: !! | AL25: Malak Hatem | AM25: Clara | AW25: Reeem | AX25: Reem Abdelhamid | AY25: Ahmed | BD25: Habiba Ashraf | BE25: Eman | BP25: Hania Hany | BQ25: Eman | BV25: Zeina mohamed salah | BW25: Ahmed
N26: Malak Ehab | O26: Ahmed | T26: Sama Sherif | U26: Esraa | AF26: Farida Atwa | AG26: Ahmed | AK26: !! | AL26: Morouj Hatem | AM26: Clara | AW26: Fayrooz | AX26: Fayrouz Mohamed Abd elmoaty | AY26: Ahmed | BD26: Celine Sameh | BE26: Eman | BP26: Salma Osama | BQ26: Eman | BV26: Malak Ehab | BW26: Ahmed
N27: Aliaa Ahmed | O27: Ahmed | T27: Sara Khaled | U27: Esraa | AF27: Farida Atwa | AG27: Ahmed | AK27: !! | AL27: Arwa Ahmed Abbas | AM27: Clara | AW27: Kenzyy | AX27: Kenzy Khaled | AY27: Ahmed | BD27: Hania Hany | BE27: Eman | BP27: Salma Nagy | BQ27: Ahmed | BV27: Farida Atwa | BW27: Ahmed
N28: Maram Khaled | O28: Ahmed | T28: Shahd Elsaid | U28: Esraa | AF28: Farida Atwa | AG28: Ahmed | AK28: !! | AL28: Arwa Ahmed Abbas | AM28: Clara | AX28: Hajar Abdelwahab | AY28: Ahmed | BD28: Walaa | BE28: Maryam | BP28: Farida Atwa | BQ28: Ahmed | BV28: Fayrouz Mohamed Abd elmoaty | BW28: Ahmed
T29: Shahd Elsaid | U29: Esraa | AF29: Salma Nagy | AG29: Ahmed | AL29: Youmna Wael | AM29: Clara | AX29: Aliaa Ahmed | AY29: Ahmed | BD29: Salma | BE29: Maryam | BP29: Ganna Elkhayat | BQ29: Ahmed | BV29: Emma Fadi Fouad | BW29: Ahmed
T30: yasmine Ahmed | U30: Esraa | AF30: Kenzy Khaled | AG30: Ahmed | AK30: Yomnaa | AL30: Youmna Wael | AM30: Clara | AX30: Maya Mohamed | AY30: Ahmed | BD30: Kenzy | BE30: Maryam | BP30: Sara Ibrahim | BQ30: Ahmed | BV30: Hallah Mahmoud Taher | BW30: Ahmed
T31: yasmine Ahmed | U31: Esraa | AF31: Emma Fadi Fouad | AG31: Ahmed | AK31: Ayaa | AL31: Aya khaled | AM31: Ahmed | AX31: Mariam Amr Arafa | AY31: Ahmed | BD31: Tala Ahmed | BE31: Maryam | BP31: Joudy Reda | BQ31: Ahmed
T32: Leen Ghoneim | U32: Esraa | AF32: Zeina mohamed salah | AG32: Ahmed | AK32: Zeinaa | AL32: Zeina mohamed salah | AM32: Ahmed | AX32: Maggie Mostafa Shams | AY32: Ahmed | BD32: Tala Ahmed | BE32: Maryam | BP32: Nadine Mostafa | BQ32: Ahmed
T33: Mariam Ashraf | U33: Ahmed | AF33: Joudy Reda | AG33: Ahmed | AL33: Hend Ahmed | AM33: Ahmed | BD33: Lobna Yasser | BE33: Maryam | BP33: Kenzy Khaled | BQ33: Ahmed
T34: Noor Abdenbi | U34: Ahmed | AF34: Farah Magdy | AG34: Ahmed | AL34: Menna Mohamed Abdelrashid | AM34: Ahmed | BD34: Arwa Ahmed Abbas | BE34: Clara | BP34: Malak Ehab | BQ34: Ahmed
S35: Charlie | T35: Charlotte Nash | U35: Ahmed | AL35: Maggie Mostafa Shams | AM35: Ahmed | BD35: Arwa Ahmed Abbas | BE35: Clara | BP35: Fayrouz Mohamed Abd elmoaty | BQ35: Ahmed
S36: Malak | T36: Malak Ehab | U36: Ahmed | AL36: Hallah Mahmoud Taher | AM36: Ahmed | BD36: Youmna Wael | BE36: Clara | BP36: Fatima | BQ36: Ahmed
S37: Aya | T37: Aya khaled | U37: Ahmed | AL37: Aliaa Ahmed | AM37: Ahmed | BD37: Youmna Wael | BE37: Clara | BP37: Elina george | BQ37: Ahmed
S38: Arwa | T38: Arwa Sherif Ibrahim | U38: Ahmed | AL38: Farah Magdy | AM38: Ahmed | BD38: Maya stive | BE38: Clara | BP38: Hajar Abdelwahab | BQ38: Ahmed
T39: Zeina mohamed salah | U39: Ahmed | BD39: Maya stive | BE39: Clara | BP39: Mariam Amr Arafa | BQ39: Ahmed
T40: Hend Ahmed | U40: Ahmed | BD40: Hayat Walid | BE40: Clara | BP40: Hallah Mahmoud Taher | BQ40: Ahmed
...

Sheet November Bundles
A1: DOP | B1: Amount | C1: L.Month | D1: Paid | E1: Total | F1: AB | G1: Off-Ice | H1: Attend | I1: Total | J1: Trainee/ Day
B3: 2800 | C3: 0 | D3: 8 | E3: =D3+C3 -> 8 | G3: =COUNTIF('Off-Ice Attendence'!$A$1:$P$34,J3) -> 0 | H3: =COUNTIF('November 2025 Attendence'!A:BY,J3) -> 8 | I3: =E3-H3-F3 -> 0 | J3: Nada Hany
B4: 2800 | C4: 0 | D4: 8 | E4: =D4+C4 -> 8 | G4: =COUNTIF('Off-Ice Attendence'!$A$1:$P$34,J4) -> 0 | H4: =COUNTIF('November 2025 Attendence'!A:BY,J4) -> 8 | I4: =E4-H4-F4 -> 0 | J4: Joud Mohamed
B5: 2800 | C5: 0 | D5: 8 | E5: =D5+C5 -> 8 | G5: =COUNTIF('Off-Ice Attendence'!$A$1:$P$34,J5) -> 1 | H5: =COUNTIF('November 2025 Attendence'!A:BY,J5) -> 7 | I5: =E5-H5-F5 -> 1 | J5: Mostafa Mohamed Hassan
B6: 1500 | C6: 0 | D6: 4 | E6: =D6+C6 -> 4 | G6: =COUNTIF('Off-Ice Attendence'!$A$1:$P$34,J6) -> 0 | H6: =COUNTIF('November 2025 Attendence'!A:BY,J6) -> 3 | I6: =E6-H6-F6 -> 1 | J6: Leen Ghoneim
B7: 2800 | C7: 0 | D7: 8 | E7: =D7+C7 -> 8 | G7: =COUNTIF('Off-Ice Attendence'!$A$1:$P$34,J7) -> 0 | H7: =COUNTIF('November 2025 Attendence'!A:BY,J7) -> 8 | I7: =E7-H7-F7 -> 0 | J7: Sama Sherif
B8: 1500 | C8: 0 | D8: 4 | E8: =D8+C8 -> 4 | F8: -1 | G8: =COUNTIF('Off-Ice Attendence'!$A$1:$P$34,J8) -> 1 | H8: =COUNTIF('November 2025 Attendence'!A:BY,J8) -> 5 | I8: =E8-H8-F8 -> 0 | J8: Noura Wael
B9: 400*1 | C9: 0 | D9: 1 | E9: =D9+C9 -> 1 | G9: =COUNTIF('Off-Ice Attendence'!$A$1:$P$34,J9) -> 0 | H9: =COUNTIF('November 2025 Attendence'!A:BY,J9) -> 1 | I9: =E9-H9-F9 -> 0 | J9: Somaia Samer
B10: 1500 | C10: 2 | D10: 4 | E10: =D10+C10 -> 6 | G10: =COUNTIF('Off-Ice Attendence'!$A$1:$P$34,J10) -> 0 | H10: =COUNTIF('November 2025 Attendence'!A:BY,J10) -> 6 | I10: =E10-H10-F10 -> 0 | J10: Sara Khaled
B11: 1500 | C11: 0 | D11: 4 | E11: =D11+C11 -> 4 | G11: =COUNTIF('Off-Ice Attendence'!$A$1:$P$34,J11) -> 0 | H11: =COUNTIF('November 2025 Attendence'!A:BY,J11) -> 4 | I11: =E11-H11-F11 -> 0 | J11: Mona Maamoun
B12: 1500 | C12: 0 | D12: 4 | E12: =D12+C12 -> 4 | G12: =COUNTIF('Off-Ice Attendence'!$A$1:$P$34,J12) -> 0 | H12: =COUNTIF('November 2025 Attendence'!A:BY,J12) -> 4 | I12: =E12-H12-F12 -> 0 | J12: Fayrouz Mohamed Ibrahim
B13: 2800 | C13: 0 | D13: 8 | E13: =D13+C13 -> 8 | G13: =COUNTIF('Off-Ice Attendence'!$A$1:$P$34,J13) -> 0 | H13: =COUNTIF('November 2025 Attendence'!A:BY,J13) -> 8 | I13: =E13-H13-F13 -> 0 | J13: Shahd elsaid
B14: 2800 | C14: 0 | D14: 8 | E14: =D14+C14 -> 8 | F14: 2 | G14: =COUNTIF('Off-Ice Attendence'!$A$1:$P$34,J14) -> 0 | H14: =COUNTIF('November 2025 Attendence'!A:BY,J14) -> 4 | I14: =E14-H14-F14 -> 2 | J14: Lara Mostafa
B15: 400*1 | C15: 1 | D15: 2 | E15: =D15+C15 -> 3 | G15: =COUNTIF('Off-Ice Attendence'!$A$1:$P$34,J15) -> 0 | H15: =COUNTIF('November 2025 Attendence'!A:BY,J15) -> 3 | I15: =E15-H15-F15 -> 0 | J15: Yasmine Ahmed
B16: 400*1 | C16: 0 | D16: 2 | E16: =D16+C16 -> 2 | G16: =COUNTIF('Off-Ice Attendence'!$A$1:$P$34,J16) -> 0 | H16: =COUNTIF('November 2025 Attendence'!A:BY,J16) -> 2 | I16: =E16-H16-F16 -> 0 | J16: Laila Ahmed
B17: 400*1 | C17: 0 | D17: 2 | E17: =D17+C17 -> 2 | G17: =COUNTIF('Off-Ice Attendence'!$A$1:$P$34,J17) -> 0 | H17: =COUNTIF('November 2025 Attendence'!A:BY,J17) -> 2 | I17: =E17-H17-F17 -> 0 | J17: Mariam Mohamed Hassan
B18: Ahmed | H18: 2 | I18: 0 | J18: Zeina mohamed salah
B19: Ahmed | H19: 2 | I19: 0 | J19: Kenzy Khaled
B20: Ahmed | H20: 1 | I20: 0 | J20: Maya Mohamed
B21: Maryam | H21: 1 | I21: 0 | J21: Tala Ahmed
C22: L.Month | D22: Paid | E22: Total | F22: AB | G22: Off-Ice | H22: Attend | I22: Total
B23: 2800 | C23: 3 | D23: 8 | E23: =D23+C23 -> 11 | G23: =COUNTIF('Off-Ice Attendence'!$A$1:$P$34,J23) -> 0 | H23: =COUNTIF('November 2025 Attendence'!A:BY,J23) -> 11 | I23: =E23-H23-F23 -> 0 | J23: Arwa Ahmed Abbas
B24: 1500 | C24: 2 | D24: 4 | E24: =D24+C24 -> 6 | G24: =COUNTIF('Off-Ice Attendence'!$A$1:$P$34,J24) -> 1 | H24: =COUNTIF('November 2025 Attendence'!A:BY,J24) -> 6 | I24: =E24-H24-F24 -> 0 | J24: youmna wael
B25: 1500 | C25: 1 | D25: 4 | E25: =D25+C25 -> 5 | G25: =COUNTIF('Off-Ice Attendence'!$A$1:$P$34,J25) -> 0 | H25: =COUNTIF('November 2025 Attendence'!A:BY,J25) -> 5 | I25: =E25-H25-F25 -> 0 | J25: Maya stive
B26: 1500 | C26: 3 | E26: =D26+C26 -> 3 | G26: =COUNTIF('Off-Ice Attendence'!$A$1:$P$34,J26) -> 0 | H26: =COUNTIF('November 2025 Attendence'!A:BY,J26) -> 1 | I26: =E26-H26-F26 -> 2 | J26: Retaj Mohamed
B27: 1500 | C27: 3 | E27: =D27+C27 -> 3 | G27: =COUNTIF('Off-Ice Attendence'!$A$1:$P$34,J27) -> 0 | H27: =COUNTIF('November 2025 Attendence'!A:BY,J27) -> 3 | I27: =E27-H27-F27 -> 0 | J27: Malak Hatem
B28: 400 | C28: 1 | E28: =D28+C28 -> 1 | G28: =COUNTIF('Off-Ice Attendence'!$A$1:$P$34,J28) -> 0 | H28: =COUNTIF('November 2025 Attendence'!A:BY,J28) -> 1 | I28: =E28-H28-F28 -> 0 | J28: Morouj Hatem
B29: 400 | C29: 0 | D29: 2 | E29: =D29+C29 -> 2 | G29: =COUNTIF('Off-Ice Attendence'!$A$1:$P$34,J29) -> 0 | H29: =COUNTIF('November 2025 Attendence'!A:BY,J29) -> 2 | I29: =E29-H29-F29 -> 0 | J29: Hanan Elsheikh
B30: Ahmed | C30: 0 | D30: 3 | E30: =D30+C30 -> 3 | G30: =COUNTIF('Off-Ice Attendence'!$A$1:$P$34,J30) -> 0 | H30: =COUNTIF('November 2025 Attendence'!A:BY,J30) -> 3 | I30: =E30-H30-F30 -> 0 | J30: Hayat Walid
B31: Ahmed | C31: 0 | D31: 1 | E31: =D31+C31 -> 1 | G31: =COUNTIF('Off-Ice Attendence'!$A$1:$P$34,J31) -> 0 | H31: =COUNTIF('November 2025 Attendence'!A:BY,J31) -> 1 | I31: =E31-H31-F31 -> 0 | J31: Anas Shaarawy
C32: L.Month | D32: Paid | E32: Total | F32: AB | G32: Off-Ice | H32: Attend | I32: Total
B33: 1500 | C33: 1 | D33: 4 | E33: =D33+C33 -> 5 | G33: =COUNTIF('Off-Ice Attendence'!$A$1:$P$34,J33) -> 0 | H33: =COUNTIF('November 2025 Attendence'!A:BY,J33) -> 2 | I33: =E33-H33-F33 -> 3 | J33: Kenzy
B34: 1500 | C34: 2 | D34: 4 | E34: =D34+C34 -> 6 | G34: =COUNTIF('Off-Ice Attendence'!$A$1:$P$34,J34) -> 0 | H34: =COUNTIF('November 2025 Attendence'!A:BY,J34) -> 1 | I34: =E34-H34-F34 -> 5 | J34: Yasmine Mahmoud
B35: 2800 | C35: -1 | D35: 8 | E35: =D35+C35 -> 7 | G35: =COUNTIF('Off-Ice Attendence'!$A$1:$P$34,J35) -> 0 | H35: =COUNTIF('November 2025 Attendence'!A:BY,J35) -> 1 | I35: =E35-H35-F35 -> 6 | J35: Habiba Eldemerdash
B36: 1500 | C36: 1 | D36: 4 | E36: =D36+C36 -> 5 | G36: =COUNTIF('Off-Ice Attendence'!$A$1:$P$34,J36) -> 0 | H36: =COUNTIF('November 2025 Attendence'!A:BY,J36) -> 2 | I36: =E36-H36-F36 -> 3 | J36: Lobna Yasser
B37: 2800 | C37: 5 | E37: =D37+C37 -> 5 | G37: =COUNTIF('Off-Ice Attendence'!$A$1:$P$34,J37) -> 0 | H37: =COUNTIF('November 2025 Attendence'!A:BY,J37) -> 1 | I37: =E37-H37-F37 -> 4 | J37: Nancy Amin
B38: 1500 | C38: 6 | E38: =D38+C38 -> 6 | G38: =COUNTIF('Off-Ice Attendence'!$A$1:$P$34,J38) -> 0 | H38: =COUNTIF('November 2025 Attendence'!A:BY,J38) -> 6 | I38: =E38-H38-F38 -> 0 | J38: Tala Ahmed
B39: 1500 | C39: -1 | E39: =D39+C39 -> -1 | G39: =COUNTIF('Off-Ice Attendence'!$A$1:$P$34,J39) -> 0 | H39: =COUNTIF('November 2025 Attendence'!A:BY,J39) -> 1 | I39: =E39-H39-F39 -> -2 | J39: Nareman Osama
B40: 1500 | C40: 0 | D40: 4 | E40: =D40+C40 -> 4 | G40: =COUNTIF('Off-Ice Attendence'!$A$1:$P$34,J40) -> 0 | H40: =COUNTIF('November 2025 Attendence'!A:BY,J40) -> 2 | I40: =E40-H40-F40 -> 2 | J40: Dina Motawea
B41: 1500 | C41: 0 | D41: 4 | E41: =D41+C41 -> 4 | G41: =COUNTIF('Off-Ice Attendence'!$A$1:$P$34,J41) -> 0 | H41: =COUNTIF('November 2025 Attendence'!A:BY,J41) -> 2 | I41: =E41-H41-F41 -> 2 | J41: Malika Mohamed
...

Sheet October Memberships
A1: Member | B1: Level | C1: Coach | D1: Bundle | E1: Amount | F1: Discount | G1: DOP | H1: Paid to | I1: Pain in
A2: Mostafa Mohamed Hassan | B2: Beta | C2: Esraa | D2: On-Ice Silver | E2: 2800 | H2: Ahmed
A3: Mona Maamoun | B3: Beta | C3: Esraa | D3: On-Ice Bronze | E3: 1500 | G3: 45934 | H3: Esraa | I3: Instapay
A4: Sama Sherif | B4: Gamma | C4: Esraa | D4: On-Ice Bronze | E4: 1500 | G4: 45934 | H4: Esraa | I4: Cash
A5: Noura Wael | B5: Gamma | C5: Esraa | D5: On-Ice Bronze | E5: 1500 | G5: 45934 | H5: Esraa | I5: Instapay
A6: Somaia Samer | B6: Beta | C6: Esraa | D6: On-Ice Bronze | E6: 1500 | G6: 45934 | H6: Esraa | I6: Instapay
A7: Sara Khaled | B7: Beta | C7: Esraa | D7: On-Ice Bronze | E7: 1500 | G7: 45934 | H7: Esraa | I7: Instapay
A8: Shahd Elsaid | B8: Pre-Alpha | C8: Esraa | D8: On-Ice Silver | E8: 2800 | G8: 45941 | H8: Esraa | I8: Instapay
A9: Fayrouz Mohamed Ibrahim | B9: Gamma | C9: Esraa | D9: On-Ice Bronze | E9: 1500 | G9: 45934 | H9: Esraa | I9: Instapay
A10: Nada Hany | B10: Freestyle 1 | C10: Esraa | D10: On-Ice Silver | E10: 2800 | G10: 45936 | H10: Esraa | I10: Cash
A11: Joud Mohamed | B11: Delta | C11: Esraa | D11: On-Ice Silver | E11: 2800 | G11: 45937 | H11: Esraa | I11: Instapay
A12: Lorina Hany | B12: Freestyle 2 | C12: Esraa | D12: On-Ice Bronze | E12: 1500 | G12: 45934 | H12: Ahmed | I12: Instapay
A13: Shahd Khaled | B13: Beta | C13: Esraa | D13: On-Ice Bronze | E13: 1500 | G13: 45941 | H13: Ahmed | I13: Cash
A14: Laila Ahmed | B14: Delta | C14: Esraa | D14: Per Session | E14: 400 | H14: Ahmed
A15: Yasmine Ahmed | B15: Alpha | C15: Esraa | D15: On-Ice Bronze | E15: 1500 | H15: Ahmed
A16: Arwa Ahmed Abbas | B16: Freestyle 3 | C16: Clara | D16: On-Ice Silver | E16: 2800 | H16: Ahmed
A17: youmna wael | B17: Freestyle 4 | C17: Clara | D17: On-Ice Silver | E17: 2800 | H17: Ahmed
A18: Jana Mahmoud | B18: Beta | C18: Clara | D18: On-Ice Bronze | E18: 1500 | H18: Ahmed
A19: Maya stive | B19: Beta | C19: Clara | D19: On-Ice Bronze | E19: 1500 | H19: Ahmed
A20: Retaj Mohamed | B20: Beta | C20: Clara | D20: On-Ice Bronze | E20: 1500 | H20: Ahmed
A21: Malak Hatem | B21: Beta | C21: Clara | D21: On-Ice Bronze | E21: 1500 | H21: Ahmed
A22: Morouj Hatem | B22: Beta | C22: Clara | D22: On-Ice Bronze | E22: 1500 | H22: Ahmed
A23: Hanan Elsheikh | B23: Freestyle 2 | C23: Clara | D23: Per Session | E23: 400 | H23: Clara | I23: Cash
A24: Kenzy | C24: Maryam | D24: On-Ice Bronze | E24: 1500 | G24: 45941 | H24: Maryam
A25: Yasmine Mahmoud | B25: Beta | C25: Maryam | D25: On-Ice Bronze | E25: 1500 | G25: 45931 | H25: Maryam
A26: Habiba Eldemerdash | B26: Freestyle 2 | C26: Maryam | D26: On-Ice Silver | E26: 2800 | G26: 45956 | H26: Maryam
A27: Lobna Yasser | B27: Alpha | C27: Maryam
A28: Amany | C28: Maryam | D28: On-Ice Bronze | E28: 1500 | G28: 45941 | H28: Maryam
A29: Tala Ahmed | B29: Gamma | C29: Maryam | D29: On-Ice Silver | E29: 2800 | G29: 45948 | H29: Maryam
A30: Nour Shatout | B30: Beta | C30: Maryam | D30: On-Ice Silver | E30: 2800 | G30: 45932 | H30: Maryam
A31: Ethar Fadl | B31: Pre-Alpha | C31: Maryam | D31: Per Session | E31: 400 | H31: Maryam
A32: Nareman Osama | C32: Maryam
A33: Nouran Mohsen | C33: Hajar | D33: On-Ice Bronze | E33: 1500 | H33: Ahmed
A34: Fatima Elhawary | C34: Hajar | D34: On-Ice Bronze | E34: 1500 | H34: Ahmed
A35: Lili Elhawary | C35: Hajar | D35: On-Ice Bronze | E35: 1500 | F35: 150 | H35: Ahmed
A36: Injy Ashraf | C36: Hajar | D36: On-Ice Bronze | E36: 1500 | H36: Ahmed
A37: Dana Arafa | C37: Hajar | D37: Per Session | E37: 400 | H37: Ahmed
A38: Layla Mohamed Foad | C38: Hajar | D38: Per Session | E38: 400 | H38: Ahmed
A39: Caroline | C39: Hajar | D39: Per Session | E39: 400 | H39: Ahmed
A40: Mariam el hodeiby | B40: Gamma | C40: Eman | D40: On-Ice Silver | E40: 2800 | H40: Ahmed
...
