Workbook

Sheet Data
A1: Bundles | E1: Coach | F1: Rink | H1: Group | I1: Level | J1: Coach
A2: Type | B2: Hours | C2: Fees | D2: Cash | E2: Ahmed | F2: ELMalahy | H2: Kids | I2: Kids | J2: Ahmed /clara
A3: On-Ice Bronze | B3: 4 | C3: 1800 | D3: Instapay | E3: Esraa | F3: SunCity | H3: Pre-bronze | I3: Pre-Alpha | J3: Eman
A4: On-Ice Silver | B4: 8 | C4: 3400 | E4: Maryam | F4: Genana | I4: Alpha
A5: On-Ice Gold | B5: 12 | C5: 4800 | E5: Hajar | F5: Both | I5: Beta | J5: Hajar
E6: Clara | H6: Bronze | I6: Gamma
A7: Off- Ice Bronze | B7: 4 | C7: 800 | E7: Eman | I7: Delta | J7: Esraa
A8: Off- Ice Silver | B8: 8 | C8: 1400 | I8: Freestyle 1
A9: Off- Ice Gold | B9: 12 | C9: 2000 | H9: Silver | I9: Freestyle 2 | J9: Clara
I10: Freestyle 3 | J10: Maryam
A11: Private | B11: 1 | C11: 700 | I11: Freestyle 4
A12: Per Session | B12: 1 | C12: 500
H13: Gold | I13: Freestyle 5 | J13: Ahmed
A14: Off-On Ice Bronze | B14: 4-4 | C14: 3600 | I14: Freestyle 6
A15: Off-On Ice Silver | B15: 8-4 | C15: 4200 | I15: Freestyle 7
A16: Off-On Ice Gold | B16: 12-8 | C16: 6200 | I16: Freestyle 8
I17: Freestyle 9
I18: Freestyle 10
A24: Levels | B24: Kids | D24: Pre-Alpha : Beta | F24: Gamma : FS1 | H24: FS2: FS4 | J24: FS5 : FS10
A25: Level's Name | B25: Kids | D25: Pre-bronze | F25: Bronze | H25: Silver | J25: Gold
B26: Kids 1 | C26: Kids 2 | D26: Pre-bronze 1 | E26: Pre-bronze 2 | F26: Bronze 1 | G26: Bronze 2 | H26: Silver 1 | I26: Silver 2 | J26: Gold | K26: Elite
D27: Pre-Alpha | E27: Beta | F27: Gamma : Delta | G27: FS1 | H27: FS2:FS3 | I27: FS4
A28: Coach | B28: Saad | C28: Clara | D28: Eman | E28: Esraa | F28: Esraa | G28: Hajer | H28: Maryem / Clara | I28: Saad / Maryem | J28: saad

Sheet Traniees Name & Package
A1: Membership N | B1: Name | F1: Level
C2: Bundles | D2: Price | E2: Coach
A3: 1 | B3: Ahmed saad | D3: 0 | E3: Ahmed | F3: Freestyle 10
A4: 2 | B4: Shaimaa El-Adl | D4: 0 | E4: Ahmed
A5: 3 | B5: Nada Khaled Kassab | D5: 0 | E5: Ahmed
A6: 4 | B6: Maryam mohamed | D6: 0 | E6: Ahmed
A7: 5 | B7: Sally Elziady | D7: 0 | E7: Ahmed
A8: 6 | B8: Hajar Munir | D8: 0 | E8: Ahmed
A9: 7 | B9: Clara Amgad | D9: 0 | E9: Ahmed
A10: 8 | B10: Esraa Nabil | D10: 0 | E10: Ahmed
A11: 9 | B11: Salma Nagy | D11: 0 | E11: Ahmed
A12: 10 | B12: Eman moustafa | D12: 0 | E12: Ahmed
A13: 11 | B13: Maria Mostafa | D13: 0 | E13: Ahmed
A14: 12 | B14: Aya khaled | D14: 0 | E14: Ahmed
A15: 13 | B15: Ganna Elkhayat | D15: 0 | E15: Ahmed
... A32: 30 | B32: Zeina mohamed salah | D32: 0 | E32: Ahmed
A33: 31 | B33: Lorina Hany | E33: Esraa
A34: 32 | B34: Julina Hany | E34: Clara
A35: 33 | B35: Robina Hany | E35: Clara
A36: 34 | B36: Jamila Amr Salem | D36: 0 | E36: Ahmed
A37: 35 | B37: Doaa El Komi | D37: 0 | E37: Eman
A38: 36 | B38: Farida Atwa | D38: 0 | E38: Ahmed
A39: 37 | B39: Reem Abdelhamid | D39: 0 | E39: Ahmed
A40: 38 | B40: Injy Ashraf | E40: Eman
A41: 39 | B41: Mariam Ashraf | D41: 0 | E41: Ahmed
A42: 40 | B42: Maya Ashraf | D42: 0 | E42: Ahmed
A43: 41 | B43: Youmna Wael | D43: 0 | E43: Ahmed
A44: 42 | B44: Nada Wael | D44: 0 | E44: Ahmed
A45: 43 | B45: Laila Ahmed | D45: 0 | E45: Esraa
A46: 44 | B46: Alya Khaled | D46: 0 | E46: Ahmed
A47: 45 | B47: Arwa Sherif Ibrahim | D47: 0 | E47: Ahmed
A48: 46 | B48: Deyala Ahmed Abousamra | D48: 0 | E48: Ahmed
A49: 47 | B49: Rozana Ahmed Abousamra | D49: 0 | E49: Ahmed
A50: 48 | B50: Jaida Ayman badawi | D50: 0 | E50: Ahmed
A51: 49 | B51: Hana Abdelrehim | D51: 0 | E51: Ahmed
A52: 50 | B52: Nada Hany | D52: 0 | E52: Esraa
... A62: 60 | B62: Elina | D62: 0 | E62: Ahmed
A63: 61 | B63: Maya Mohamed | E63: Esraa
A64: 62 | B64: Caroline | D64: 0 | E64: Hajar
A65: 63 | B65: Malak sherif | D65: 0 | E65: Ahmed
...

Sheet June 2026 Memberships
A1: Member | B1: Level | C1: Coach | D1: Bundle | E1: Amount | F1: Discount | G1: DOP | H1: Paid to | I1: Pain in
A2: Hanan Alaa | B2: Pre-Alpha | C2: Esraa | D2: On-Ice Silver | E2: 3400 | G2: 46176 | H2: Esraa | I2: Instapay
A3: Nancy Ahmed | B3: Pre-Alpha | C3: Esraa | D3: On-Ice Silver | E3: 3400 | G3: 46177 | H3: Esraa | I3: Instapay
A4: Yasmina Sherwella | B4: Beta | C4: Esraa | D4: On-Ice Silver | E4: 3400 | G4: 46177 | H4: Esraa | I4: Instapay
A5: Menna Yehia | B5: Alpha | C5: Esraa | D5: On-Ice Silver | E5: 3400 | G5: 46177 | H5: Esraa | I5: Instapay
A6: Shahd Hesham | B6: Alpha | C6: Esraa | D6: On-Ice Bronze | E6: 1800 | G6: 46178 | H6: Esraa | I6: Instapay
A7: Jumana Ali | B7: Pre-Alpha | C7: Esraa | D7: On-Ice Bronze | E7: 1800 | G7: 46179 | H7: Esraa | I7: Instapay
A8: Joudy Reda | B8: Delta | C8: Ahmed | D8: On-Ice Bronze | E8: 1800 | G8: 46179 | H8: Esraa | I8: Cash
A9: Hana Karam | B9: Pre-Alpha | C9: Esraa | D9: On-Ice Bronze | E9: 1800 | G9: 46179 | H9: Esraa | I9: Cash
A10: Miechalle Effat | B10: Beta | C10: Esraa | D10: Per Session | E10: 500 | G10: 46181 | H10: Esraa | I10: Instapay
A11: Sara Khaled | B11: Freestyle 1 | C11: Esraa | D11: On-Ice Bronze | E11: 1800 | G11: 46183 | H11: Esraa | I11: Instapay
A12: Mariam Hashad | B12: Alpha | C12: Esraa | D12: On-Ice Bronze | E12: 1800 | G12: 46183 | H12: Esraa | I12: Cash
A13: Veronia Sameh | B13: Pre-Alpha | C13: Esraa | D13: Private | E13: 700 | F13: 100 | G13: 46187 | H13: Esraa | I13: Cash
A14: Miechalle Effat | B14: Beta | C14: Esraa | D14: Per Session | E14: 500 | G14: 46187 | H14: Esraa | I14: Instapay
A15: Somaia Samer | B15: Gamma | C15: Esraa | D15: Per Session | E15: 500 | G15: 46187 | H15: Esraa | I15: Instapay
A16: Veronia Sameh | B16: Pre-Alpha | C16: Esraa | D16: Per Session | E16: 500 | G16: 46190 | H16: Esraa | I16: Cash
A17: Veronia Sameh | B17: Pre-Alpha | C17: Esraa | D17: Per Session | E17: 500 | G17: 46174 | H17: Esraa | I17: Cash
A18: Veronia Sameh | B18: Pre-Alpha | C18: Esraa | D18: Per Session | E18: 500 | G18: 46197 | H18: Esraa | I18: Cash
A19: Shokran Sameh | B19: Beta | C19: Esraa | D19: Per Session | E19: 500 | G19: 46202 | H19: Esraa | I19: Instapay
A20: Shokran Sameh | B20: Beta | C20: Esraa | D20: Per Session | E20: 500 | G20: 46202 | H20: Esraa | I20: Instapay

Sheet Off-Ice Attendence
A1: 46174 | B1: 46175 | C1: 46176 | D1: 46177 | E1: 46178 | F1: 46179 | G1: 46180 | H1: 46181 | I1: 46182 | J1: 46183 | K1: 46184 | L1: 46185 | M1: 46186 | N1: 46187 | O1: 46188 | P1: 46189 | Q1: 46190 | R1: 46191 | S1: 46192 | T1: 46193 | U1: 46194 | V1: 46195 | W1: 46196 | X1: 46197 | Y1: 46198 | Z1: 46199 | AA1: 46200 | AB1: 46201 | AC1: 46202 | AD1: 46203

Sheet June 2026 Attendence
A1: 46174 | D1: 46175 | G1: 46176 | J1: 46177 | M1: 46178 | P1: 46179 | S1: 46180 | V1: 46181 | Y1: 46182 | AB1: 46183 | AE1: 46184 | AH1: 46185 | AK1: 46186 | AN1: 46187 | AQ1: 46188 | AT1: 46189 | AW1: 46190 | AZ1: 46191 | BC1: 46192 | BF1: 46193 | BI1: 46194 | BL1: 46195 | BO1: 46196 | BR1: 46197 | BU1: 46198 | BX1: 46199 | CA1: 46200 | CD1: 46201 | CG1: 46202 | CJ1: 46203
E2: Eman moustafa | F2: Coach | H2: Esraa Nabil | I2: Coach | K2: Esraa Nabil | L2: Coach | Q2: Esraa Nabil | R2: Coach | T2: Esraa Nabil | U2: Coach | W2: Eman moustafa | X2: Coach | Z2: Maryam mohamed | AA2: Coach | AC2: Esraa Nabil | AD2: Coach | AF2: Maryam mohamed | AG2: Coach | AL2: Esraa Nabil | AM2: Coach | AO2: Esraa Nabil | AP2: Coach | AR2: Eman moustafa | AS2: Coach | AU2: Clara Amgad | AV2: Coach | AX2: Esraa Nabil | AY2: Coach | BA2: Hajar Munir | BB2: Coach | BG2: Esraa Nabil | BH2: Coach | BM2: Esraa Nabil | BN2: Coach | BP2: Hajar Munir | BQ2: Coach | BS2: Esraa Nabil | BT2: Coach | BV2: Esraa Nabil | BW2: Coach | CB2: Clara Amgad | CC2: Coach | CE2: Esraa Nabil | CF2: Coach | CH2: Esraa Nabil | CI2: Coach | CK2: Eman moustafa | CL2: Coach
E3: Maryam mohamed | F3: Coach | H3: Eman moustafa | I3: Coach | K3: Hajar Munir | L3: Coach | Q3: Maryam mohamed | R3: Coach | T3: Hajar Munir | U3: Coach | W3: Nada Mohamed | X3: Eman | Z3: Clara Amgad | AA3: Coach | AC3: Eman moustafa | AD3: Coach | AF3: Hajar Munir | AG3: Coach | AL3: Hajar Munir | AM3: Coach | AO3: Hajar Munir | AP3: Coach | AR3: Anouf Omar | AS3: Eman | AU3: Eman moustafa | AV3: Coach | AX3: Eman moustafa | AY3: Coach | BA3: Maryam mohamed | BB3: Coach | BG3: Maryam mohamed | BH3: Coach | BM3: Hajar Munir | BN3: Coach | BP3: Eman moustafa | BQ3: Coach | BS3: Eman moustafa | BT3: Coach | BV3: Clara Amgad | BW3: Coach | CB3: Hajar Munir | CC3: Coach | CE3: Maryam mohamed | CF3: Coach | CH3: Hanan Alaa | CI3: Esraa | CK3: Clara Amgad | CL3: Coach
E4: Lucienda Shady | F4: Eman | H4: Hanan Alaa | I4: Esraa | K4: Maryam mohamed | L4: Coach | Q4: Eman moustafa | R4: Coach | T4: Omar Magdy | U4: Hajar | W4: Salma Ali | X4: Eman | Z4: Eman moustafa | AA4: Coach | AC4: Anouf Omar | AD4: Eman | AF4: Omar Magdy | AG4: Hajar | AL4: Eman moustafa | AM4: Coach | AO4: Omar Magdy | AP4: Hajar | AR4: Joudy Khaled | AS4: Eman | AU4: Nada Wael | AV4: Clara | AX4: Anouf Omar | AY4: Eman | BA4: Amal Fawzy | BB4: Hajar | BG4: Hajar Munir | BH4: Coach | BM4: Yasmine Walid | BN4: Hajar | BP4: Maryam mohamed | BQ4: Coach | BS4: Anouf Omar | BT4: Eman | BU4: Shereen | BW4: Clara | CB4: Eman moustafa | CC4: Coach | CE4: Hajar Munir | CF4: Coach | CH4: Nancy Ahmed | CI4: Esraa | CK4: Maryam mohamed | CL4: Coach
E5: Nada Mohamed | F5: Eman | H5: Nancy Ahmed | I5: Esraa | K5: Massa Ahmed | L5: Maryam | Q5: Clara Amgad | R5: Coach | T5: Omar Magdy | U5: Hajar | W5: Lucienda Shady | X5: Eman | Z5: Arwa Ahmed Abbas | AA5: Clara | AC5: Tia Mohamed | AD5: Eman | AF5: Omar Magdy | AG5: Hajar | AL5: Maryam mohamed | AM5: Coach | AO5: Yasmen elsaid | AP5: Hajar | AR5: Lucienda Shady | AS5: Eman | AU5: Youmna Wael | AV5: Clara | AX5: Tia Mohamed | AY5: Eman | BA5: Nouran Mohsen | BB5: Hajar | BG5: Eman moustafa | BH5: Coach | BM5: Omar Magdy | BN5: Hajar | BP5: Fatima Elhawary | BQ5: Hajar | BS5: Lydia Adel | BT5: Eman | BU5: Mayan | BW5: Clara | CB5: Maya stive | CC5: Clara | CE5: Injy Ashraf | CF5: Hajar | CH5: Jumana Ali | CI5: Esraa | CK5: Lucienda Shady | CL5: Eman
E6: Salma Ali | F6: Eman | H6: Yasmina Sherwella | I6: Esraa | K6: Massa Ahmed | L6: Maryam | Q6: Charlotte Nash | R6: Coach | T6: Yasmine Walid | U6: Hajar | W6: Hania Hany | X6: Eman | Z6: Nada Wael | AA6: Clara | AC6: Fayrouz Tamer | AD6: Eman | AF6: Amal Fawzy | AG6: Hajar | AL6: Clara Amgad | AM6: Coach | AO6: Malak Kattaya | AP6: Esraa | AU6: Maya stive | AV6: Clara | AX6: Fayrouz Tamer | AY6: Eman | BA6: Yasmine Walid | BB6: Hajar | BG6: Sara Mohamed Ali | BH6: Maryam | BM6: Hanan Alaa | BN6: Esraa | BP6: Omar Magdy | BQ6: Hajar | BS6: Fayrouz Tamer | BT6: Eman | BV6: Jumana Ali | BW6: Esraa | CB6: NerminRoushdy | CC6: Clara | CE6: Yasmine Walid | CF6: Hajar | CH6: Shokran Sameh | CI6: Esraa | CK6: Carol Ehab | CL6: Eman
E7: Shahd Khaled | F7: Eman | H7: Yasmina Sherwella | I7: Esraa | K7: Malika Ahmed | L7: Maryam | Q7: Amany | R7: Maryam | T7: Malak Kattaya | U7: Esraa | Z7: Youmna Wael | AA7: Clara | AC7: Fayrouz Tamer | AD7: Eman | AF7: Amal Fawzy | AG7: Hajar | AL7: Nouran Mohsen | AM7: Hajar | AO7: Menna Yehia | AP7: Esraa | AU7: Arwa Ahmed Abbas | AV7: Clara | AX7: Darine Tamer | AY7: Eman | BA7: Hana Tamer | BB7: Hajar | BG7: Allaa | BH7: Maryam | BM7: Nancy Ahmed | BN7: Esraa | BP7: Nawara Yasser | BQ7: Eman | BS7: Tia Mohamed | BT7: Eman | BV7: Farida Emad | BW7: Esraa | CB7: Amal Fawzy | CC7: Hajar | CE7: Omar Magdy | CF7: Hajar | CH7: Shahd Hesham | CI7: Esraa | CK7: Nada Wael | CL7: Clara
E8: Sama Hussein | F8: Maryam | H8: Menna Yehia | I8: Esraa | K8: Malika Ahmed | L8: Maryam | Q8: Hajar Abdelwahab | R8: Maryam | T8: Hanan Alaa | U8: Esraa | Z8: Sama Hussein | AA8: Maryam | AC8: Darine Tamer | AD8: Eman | AF8: Hana Tamer | AG8: Hajar | AL8: Nouran Mohsen | AM8: Hajar | AO8: Shokran Sameh | AP8: Esraa | AU8: Maya Emad | AV8: Eman | AX8: Nawara Yasser | AY8: Eman | BA8: Sama Hussein | BB8: Maryam | BG8: Kenzy | BH8: Maryam | BM8: Yasmina Sherwella | BN8: Esraa | BP8: Lucienda Shady | BQ8: Eman | BS8: Celine Sameh | BT8: Eman | BV8: Mostafa Mohamed Hassan | BW8: Esraa | CB8: Yasmine Walid | CC8: Hajar | CE8: Angila John | CF8: Maryam | CG8: Esraa | CH8: Joudy Reda | CI8: Ahmed | CK8: Youmna Wael | CL8: Clara
E9: Elina Kamel | F9: Maryam | G9: Esraa | H9: Fayrouz Mohamed Abd elmoaty | I9: Ahmed | K9: Angila John | L9: Maryam | Q9: Mariam Ashmawy | R9: Maryam | T9: Shokran Sameh | U9: Esraa | Z9: Amany | AA9: Maryam | AC9: Salma Osama | AD9: Eman | AF9: Rose Mary | AG9: Maryam | AL9: Yasmine Walid | AM9: Hajar | AO9: Shahd Hesham | AP9: Esraa | AU9: Jana Emad | AV9: Eman | AX9: Hanan Alaa | AY9: Esraa | BG9: Elina Kamel | BH9: Maryam | BM9: Shokran Sameh | BN9: Esraa | BP9: Rawan Abdel Mohsen | BQ9: Eman | BS9: Hania Hany | BT9: Eman | CB9: Fatima Elhawary | CC9: Hajar | CE9: Elina Kamel | CF9: Maryam | CG9: Esraa | CH9: Nada Mohamed | CI9: Ahmed | CJ9: wafaa | CL9: Clara
E10: Elina Kamel | F10: Maryam | G10: Esraa | H10: Farida Atwa | I10: Ahmed | K10: Allaa | L10: Maryam | Q10: Nada Abotaleb | R10: Maryam | S10: Esraa | T10: Hanin Yehia | U10: Ahmed | Z10: Rawan Khaled | AA10: Maryam | AC10: Hanan Alaa | AD10: Esraa | AF10: Joudy George | AG10: Maryam | AL10: Yasmine Walid | AM10: Hajar | AO10: Farida Emad | AP10: Esraa | AX10: Menna Yehia | AY10: Esraa | BG10: Elina Kamel | BH10: Maryam | BP10: Joudy George | BQ10: Maryam | BS10: Salma Osama | BT10: Eman | CB10: Fatima Elhawary | CC10: Hajar | CE10: Elina Kamel | CF10: Maryam | CG10: Esraa | CH10: Salma Ali | CI10: Ahmed | CJ10: Farida | CL10: Maryam
G11: Esraa | H11: Maya Ashraf | I11: Ahmed | K11: Hana Tamer | L11: Hajar | Q11: Angila John | R11: Maryam | Z11: Hajar Abdelwahab | AA11: Maryam | AC11: Nancy Ahmed | AD11: Esraa | AF11: Allaa | AG11: Maryam | AL11: Amal Fawzy | AM11: Hajar | AO11: Hana Karam | AP11: Esraa | AX11: Shokran Sameh | AY11: Esraa | BF11: Menna Ayman | BH11: Hajar | BP11: Rose Mary | BQ11: Maryam | BS11: Hanan Alaa | BT11: Esraa | CB11: Hana Tamer | CC11: Hajar | CE11: Allaa | CF11: Maryam | CG11: Esraa | CH11: Roba Ramy | CI11: Ahmed | CK11: Sama Hussein | CL11: Maryam
G12: Esraa | H12: Arwa Sherif Ibrahim | I12: Ahmed | K12: Hana Tamer | L12: Hajar | Q12: Menna Ashraf | R12: Maryam | Y12: Farida | AA12: Maryam | AC12: Yasmina Sherwella | AD12: Esraa | AF12: Kenzy | AG12: Maryam | AL12: Celine Sameh | AM12: Eman | AO12: Veronia Sameh | AP12: Esraa | AX12: Mostafa Mohamed Hassan | AY12: Esraa | BG12: Amal Fawzy | BH12: Hajar | BP12: Amany | BQ12: Maryam | BS12: Nancy Ahmed | BT12: Esraa | CB12: Hania Hany | CC12: Eman | CE12: Sara Mohamed Ali | CF12: Maryam | CG12: Esraa | CH12: Hams Hany | CI12: Ahmed | CK12: Joudy George | CL12: Maryam
G13: Esraa | H13: Mariam Essam | I13: Ahmed | K13: Amal Fawzy | L13: Hajar | Q13: Massa Ahmed | R13: Maryam | Z13: Farah El semary | AA13: Eman | AC13: Menna Yehia | AD13: Esraa | AE13: Maryam | AF13: Hanin Yehia | AG13: Ahmed | AL13: Maya Emad | AM13: Eman | AX13: Mariam Hashad | AY13: Esraa | BG13: Nouran Mohsen | BH13: Hajar | BO13: Farida | BQ13: Maryam | BS13: Yasmina Sherwella | BT13: Esraa | CB13: Anouf Omar | CC13: Eman | CE13: Karma Morgan | CF13: Maryam | CG13: Esraa | CH13: Mai Elfeky | CI13: Ahmed | CK13: Rose Mary | CL13: Maryam
G14: Esraa | H14: Menna Mohsen | I14: Ahmed | K14: Amal Fawzy | L14: Hajar | Q14: Massa Ahmed | R14: Maryam | AC14: Sara Khaled | AD14: Esraa | AE14: Maryam | AF14: Reem Abdelhamid | AG14: Ahmed | AL14: Jana Emad | AM14: Eman | AX14: Veronia Sameh | AY14: Esraa | BG14: Anouf Omar | BH14: Eman | BS14: Mostafa Mohamed Hassan | BT14: Esraa | CB14: Fayrouz Tamer | CC14: Eman | CE14: Hanan Alaa | CF14: Esraa | CG14: Esraa | CH14: Nada Soliman | CI14: Ahmed | CK14: Menna Ashraf | CL14: Maryam
G15: Esraa | H15: Hams Hany | I15: Ahmed | K15: Omar Magdy | L15: Hajar | Q15: Malika Ahmed | R15: Maryam | AC15: Shokran Sameh | AD15: Esraa | AE15: Maryam | AF15: Arwa Sherif Ibrahim | AG15: Ahmed | AL15: Carol Ehab | AM15: Eman | BG15: Lydia Adel | BH15: Eman | BS15: Mariam Hashad | BT15: Esraa | CB15: Darine Tamer | CC15: Eman | CE15: Malak Kattaya | CF15: Esraa | CG15: Omar | CH15: Lojain Waleed | CI15: Ahmed
G16: Esraa | H16: Nada Hany | I16: Ahmed | K16: Nouran Mohsen | L16: Hajar | Q16: Malika Ahmed | R16: Maryam | AC16: Shahd Hesham | AD16: Esraa | AE16: Maryam | AF16: Farida Emad | AG16: Esraa | AL16: Hania Hany | AM16: Eman | BG16: Fayrouz Tamer | BH16: Eman | BS16: Veronia Sameh | BT16: Esraa | CB16: Shahd Khaled | CC16: Eman | CE16: Yasmina Sherwella | CF16: Esraa | CG16: Omar | CH16: Nada Tarek | CI16: Ahmed
G17: Hassan | H17: Celina Ayad | I17: Ahmed | K17: Farida Emad | L17: Esraa | Q17: Shahd Khaled | R17: Eman | AC17: Mariam Hashad | AD17: Esraa | AF17: Elina | AG17: Ahmed | AL17: Shahd Khaled | AM17: Eman | BG17: Darine Tamer | BH17: Eman | CB17: Shahd Khaled | CC17: Eman | CE17: Sara Khaled | CF17: Esraa | CG17: Omar | CH17: Nada Hatem | CI17: Ahmed
G18: Hassan | H18: Sila Abdelfattah | I18: Ahmed | K18: Malak Kattaya | L18: Esraa | Q18: Shahd Khaled | R18: Eman | AL18: Shahd Khaled | AM18: Eman | BG18: Shahd Khaled | BH18: Eman | CB18: Asser Haytham | CC18: Eman | CE18: Sara Khaled | CF18: Esraa | CG18: Alia | CH18: Maya Ashraf | CI18: Ahmed
G19: Hassan | H19: Rehab Gamal | I19: Ahmed | J19: Esraa | K19: Hanin Yehia | L19: Ahmed | Q19: Karma Amr Saad | R19: Eman | AL19: Asser Haytham | AM19: Eman | BG19: Asser Haytham | BH19: Eman | CB19: Asser Haytham | CC19: Eman | CE19: Somaia Samer | CF19: Esraa | CG19: Alia | CH19: Mariam Amr Arafa | CI19: Ahmed
G20: Fayrouz | H20: Zeinab Omar | I20: Ahmed | J20: Esraa | K20: Hanin Yehia | L20: Ahmed | Q20: Fayrouz Tamer | R20: Eman | AL20: Asser Haytham | AM20: Eman | BG20: Anglina Beshoy | BH20: Eman | CB20: Maya Emad | CC20: Eman | CE20: Somaia Samer | CF20: Esraa | CG20: Alia | CH20: Maggie Mostafa Shams | CI20: Ahmed
G21: Fayrouz | H21: Mai Elfeky | I21: Ahmed | J21: Esraa | K21: Reem Abdelhamid | L21: Ahmed | Q21: Darine Tamer | R21: Eman | AL21: Anglina Beshoy | AM21: Eman | BF21: alia | BH21: Eman | CB21: Jana Emad | CC21: Eman | CE21: Hana Karam | CF21: Esraa | CG21: Alia | CH21: Ganna Elkhayat | CI21: Ahmed
G22: Fayrouz | H22: Roba Ramy | I22: Ahmed | Q22: Anouf Omar | R22: Eman | AK22: Alia | AM22: Eman | BG22: Maya Emad | BH22: Eman | CB22: Rawan Abdel Mohsen | CC22: Eman | CD22: Esraa | CE22: Elina | CF22: Ahmed | CG22: Alia | CH22: Fayrouz Mohamed Abd elmoaty | CI22: Ahmed
G23: Eman | H23: Dana Kareem | I23: Ahmed | Q23: Nawara Yasser | R23: Eman | AL23: Kenzy | AM23: Maryam | BG23: Jana Emad | BH23: Eman | CA23: alia | CC23: Eman | CG23: Alia | CH23: Farida Atwa | CI23: Ahmed
G24: Eman | H24: Anouf Omar | I24: Ahmed | Q24: Tia Mohamed | R24: Eman | AL24: Joudy George | AM24: Maryam | BG24: Nancy Ahmed | BH24: Esraa | CA24: Ahmed | CB24: Hana Karam | CC24: Esraa | CG24: Alia | CH24: Hallah Mahmoud Taher | CI24: Ahmed
H25: Shahd Khaled | I25: Eman | Q25: Celine Sameh | R25: Eman | AL25: Rose Mary | AM25: Maryam | BG25: Malak Kattaya | BH25: Esraa
H26: Shahd Khaled | I26: Eman | Q26: Arwa Ahmed Abbas | R26: Clara | AL26: Rawan Khaled | AM26: Maryam | BG26: Menna Yehia | BH26: Esraa
H27: Nada Mohamed | I27: Eman | Q27: Maya stive | R27: Clara | AL27: Menna Ashraf | AM27: Maryam | BG27: Shokran Sameh | BH27: Esraa
H28: Nada Mohamed | I28: Eman | Q28: NerminRoushdy | R28: Clara | AL28: Arwa Ahmed Abbas | AM28: Clara | BG28: Mostafa Mohamed Hassan | BH28: Esraa
H29: Salma Ali | I29: Eman | Q29: Laila Elalfy | R29: Clara | AL29: Maya stive | AM29: Clara | BG29: Veronia Sameh | BH29: Esraa
H30: Salma Ali | I30: Eman | Q30: Omar Magdy | R30: Hajar | AL30: NerminRoushdy | AM30: Clara
H31: Nour Eldarqawy | I31: Eman | Q31: Omar Magdy | R31: Hajar | AK31: Shereen | AM31: Clara
H32: Nour Eldarqawy | I32: Eman | Q32: Yasmine Walid | R32: Hajar | AL32: Nancy Ahmed | AM32: Esraa
H33: Habiba Ashraf | I33: Eman | Q33: Nancy Ahmed | R33: Esraa | AL33: Malak Kattaya | AM33: Esraa
Q34: Malak Kattaya | R34: Esraa | AL34: Yasmina Sherwella | AM34: Esraa
Q35: Yasmina Sherwella | R35: Esraa | AL35: Menna Yehia | AM35: Esraa
Q36: Jumana Ali | R36: Esraa | AL36: Jumana Ali | AM36: Esraa
Q37: Miechalle Effat | R37: Esraa | AL37: Miechalle Effat | AM37: Esraa
Q38: Sara Khaled | R38: Esraa | AL38: Somaia Samer | AM38: Esraa
Q39: Mostafa Mohamed Hassan | R39: Esraa
P40: Esraa | Q40: Anglina Beshoy | R40: Eman
...

Sheet June 2026 Bundles
A1: DOP | B1: Amount | C1: L.Month | D1: Paid | E1: Total | F1: AB | G1: Off-Ice | H1: Attend | I1: Total | J1: Trainee/ Day
B3: - | D3: 8 | E3: =D3+C3 -> 8 | F3: 1 | G3: =COUNTIF('Off-Ice Attendence'!$A$1:$J$34,J3) -> 0 | H3: =COUNTIF('June 2026 Attendence'!A:CL,J3) -> 5 | I3: =E3-H3-F3 -> 2 | J3: Mostafa Mohamed Hassan
B4: 3400 | D4: 8 | E4: =D4+C4 -> 8 | G4: =COUNTIF('Off-Ice Attendence'!$A$1:$J$34,J4) -> 0 | H4: =COUNTIF('June 2026 Attendence'!A:CL,J4) -> 7 | I4: =E4-H4-F4 -> 1 | J4: Malak Kattaya | L4: 11 missing
B5: 3400 | C5: 2 | D5: 8 | E5: =D5+C5 -> 10 | G5: =COUNTIF('Off-Ice Attendence'!$A$1:$J$34,J5) -> 0 | H5: =COUNTIF('June 2026 Attendence'!A:CL,J5) -> 8 | I5: =E5-H5-F5 -> 2 | J5: Yasmina Sherwella | L5: 3 maryam
B6: 3400 | D6: 8 | E6: =D6+C6 -> 8 | G6: =COUNTIF('Off-Ice Attendence'!$A$1:$J$34,J6) -> 0 | H6: =COUNTIF('June 2026 Attendence'!A:CL,J6) -> 8 | I6: =E6-H6-F6 -> 0 | J6: Nancy Ahmed | L6: 3 eman
B7: 3400 | D7: 8 | E7: =D7+C7 -> 8 | G7: =COUNTIF('Off-Ice Attendence'!$A$1:$J$34,J7) -> 0 | H7: =COUNTIF('June 2026 Attendence'!A:CL,J7) -> 8 | I7: =E7-H7-F7 -> 0 | J7: Hanan Alaa | L7: 4 clara
B8: 1800 | D8: 4 | E8: =D8+C8 -> 4 | G8: =COUNTIF('Off-Ice Attendence'!$A$1:$J$34,J8) -> 0 | H8: =COUNTIF('June 2026 Attendence'!A:CL,J8) -> 3 | I8: =E8-H8-F8 -> 1 | J8: Mariam Hashad | L8: 1 Hajar
B9: 1800 | C9: -3 | D9: 8 | E9: =D9+C9 -> 5 | G9: =COUNTIF('Off-Ice Attendence'!$A$1:$J$34,J9) -> 0 | H9: =COUNTIF('June 2026 Attendence'!A:CL,J9) -> 7 | I9: =E9-H9-F9 -> -2 | J9: Shokran Sameh | L9: Plus 2 auditions from hajar
B10: 1800 | D10: 4 | E10: =D10+C10 -> 4 | G10: =COUNTIF('Off-Ice Attendence'!$A$1:$J$34,J10) -> 0 | H10: =COUNTIF('June 2026 Attendence'!A:CL,J10) -> 4 | I10: =E10-H10-F10 -> 0 | J10: Sara Khaled | L10: Plus 1 auditions from Clara
B11: 1800 | D11: 8 | E11: =D11+C11 -> 8 | G11: =COUNTIF('Off-Ice Attendence'!$A$1:$J$34,J11) -> 0 | H11: =COUNTIF('June 2026 Attendence'!A:CL,J11) -> 6 | I11: =E11-H11-F11 -> 2 | J11: Menna Yehia
B12: 1800 | D12: 4 | E12: =D12+C12 -> 4 | G12: =COUNTIF('Off-Ice Attendence'!$A$1:$J$34,J12) -> 0 | H12: =COUNTIF('June 2026 Attendence'!A:CL,J12) -> 4 | I12: =E12-H12-F12 -> 0 | J12: Jumana Ali
B13: 1800 | D13: 4 | E13: =D13+C13 -> 4 | F13: 1 | G13: =COUNTIF('Off-Ice Attendence'!$A$1:$J$34,J13) -> 0 | H13: =COUNTIF('June 2026 Attendence'!A:CL,J13) -> 3 | I13: =E13-H13-F13 -> 0 | J13: Shahd Hesham
B14: 1800 | D14: 4 | E14: =D14+C14 -> 4 | G14: =COUNTIF('Off-Ice Attendence'!$A$1:$J$34,J14) -> 0 | H14: =COUNTIF('June 2026 Attendence'!A:CL,J14) -> 4 | I14: =E14-H14-F14 -> 0 | J14: Hana Karam
B15: 1800 | D15: 4 | E15: =D15+C15 -> 4 | G15: =COUNTIF('Off-Ice Attendence'!$A$1:$J$34,J15) -> 0 | H15: =COUNTIF('June 2026 Attendence'!A:CL,J15) -> 4 | I15: =E15-H15-F15 -> 0 | J15: Farida Emad
B16: 500 | D16: 4 | E16: =D16+C16 -> 4 | G16: =COUNTIF('Off-Ice Attendence'!$A$1:$J$34,J16) -> 0 | H16: =COUNTIF('June 2026 Attendence'!A:CL,J16) -> 4 | I16: =E16-H16-F16 -> 0 | J16: Veronia Sameh
B17: 500 | D17: 2 | E17: =D17+C17 -> 2 | G17: =COUNTIF('Off-Ice Attendence'!$A$1:$J$34,J17) -> 0 | H17: =COUNTIF('June 2026 Attendence'!A:CL,J17) -> 2 | I17: =E17-H17-F17 -> 0 | J17: Miechalle Effat
B18: 500 | D18: 3 | E18: =D18+C18 -> 3 | G18: =COUNTIF('Off-Ice Attendence'!$A$1:$J$34,#REF!) -> 0 | H18: =COUNTIF('June 2026 Attendence'!A:CL,J18) -> 3 | I18: =E18-H18-F18 -> 0 | J18: Somaia Samer
B19: Eman | D19: 1 | E19: =D19+C19 -> 1 | G19: =COUNTIF('Off-Ice Attendence'!$A$1:$J$34,#REF!) -> 0 | H19: 1 | I19: =E19-H19-F19 -> 0 | J19: Anglina Beshoy
C20: L.Month | D20: Paid | E20: Total | F20: AB | G20: Off-Ice | H20: Attend | I20: Total
E21: =D21+C21 -> 0 | G21: =COUNTIF('Off-Ice Attendence'!$A$1:$J$34,J21) -> 0 | H21: =COUNTIF('June 2026 Attendence'!A:CL,J21) -> 3 | I21: =E21-H21-F21 -> -3 | J21: Youmna wael
E22: =D22+C22 -> 0 | G22: =COUNTIF('Off-Ice Attendence'!$A$1:$J$34,J22) -> 0 | H22: =COUNTIF('June 2026 Attendence'!A:CL,J22) -> 3 | I22: =E22-H22-F22 -> -3 | J22: Nada Wael
E23: =D23+C23 -> 0 | G23: =COUNTIF('Off-Ice Attendence'!$A$1:$J$34,J23) -> 0 | H23: =COUNTIF('June 2026 Attendence'!A:CL,J23) -> 4 | I23: =E23-H23-F23 -> -4 | J23: Arwa Ahmed Abbas | L23: Shereen Mohamed | M23: 6-13 / 6-25
C24: 1 | E24: =D24+C24 -> 1 | G24: =COUNTIF('Off-Ice Attendence'!$A$1:$J$34,J24) -> 0 | H24: =COUNTIF('June 2026 Attendence'!A:CL,J24) -> 4 | I24: =E24-H24-F24 -> -3 | J24: Maya stive | L24: Mayan | M24: 46198
E25: =D25+C25 -> 0 | G25: =COUNTIF('Off-Ice Attendence'!$A$1:$J$34,J25) -> 0 | H25: =COUNTIF('June 2026 Attendence'!A:CL,J25) -> 0 | I25: =E25-H25-F25 -> 0 | J25: Retaj Mohamed | L25: Wafaa | M25: 46203
E26: =D26+C26 -> 0 | G26: =COUNTIF('Off-Ice Attendence'!$A$1:$J$34,J26) -> 0 | H26: =COUNTIF('June 2026 Attendence'!A:CL,J26) -> 0 | I26: =E26-H26-F26 -> 0 | J26: Retaj Wael | L26: Aisha | M26: 46190 | N26: Audttion
E27: =D27+C27 -> 0 | G27: =COUNTIF('Off-Ice Attendence'!$A$1:$J$34,J27) -> 0 | H27: =COUNTIF('June 2026 Attendence'!A:CL,J27) -> 0 | I27: =E27-H27-F27 -> 0 | J27: Mathiew Mina
C28: 1 | E28: =D28+C28 -> 1 | G28: =COUNTIF('Off-Ice Attendence'!$A$1:$J$34,J28) -> 0 | H28: =COUNTIF('June 2026 Attendence'!A:CL,J28) -> 1 | I28: =E28-H28-F28 -> 0 | J28: Laila Elalfy
E29: =D29+C29 -> 0 | G29: =COUNTIF('Off-Ice Attendence'!$A$1:$J$34,J29) -> 0 | H29: =COUNTIF('June 2026 Attendence'!A:CL,J29) -> 0 | I29: =E29-H29-F29 -> 0 | J29: Malak Yasser
C30: 1 | E30: =D30+C30 -> 1 | G30: =COUNTIF('Off-Ice Attendence'!$A$1:$J$34,J30) -> 0 | H30: =COUNTIF('June 2026 Attendence'!A:CL,J30) -> 3 | I30: =E30-H30-F30 -> -2 | J30: NerminRoushdy
C31: L.Month | D31: Paid | E31: Total | F31: AB | G31: Off-Ice | H31: Attend | I31: Total
C32: 0 | E32: =D32+C32 -> 0 | G32: =COUNTIF('Off-Ice Attendence'!$A$1:$J$34,J32) -> 0 | H32: =COUNTIF('June 2026 Attendence'!A:CL,J32) -> 3 | I32: =E32-H32-F32 -> -3 | J32: Kenzy
C33: 1 | E33: =D33+C33 -> 1 | G33: =COUNTIF('Off-Ice Attendence'!$A$1:$J$34,J33) -> 0 | H33: =COUNTIF('June 2026 Attendence'!A:CL,J33) -> 0 | I33: =E33-H33-F33 -> 1 | J33: Yasmine Mahmoud
C34: 1 | E34: =D34+C34 -> 1 | G34: =COUNTIF('Off-Ice Attendence'!$A$1:$J$34,J34) -> 0 | H34: =COUNTIF('June 2026 Attendence'!A:CL,J34) -> 2 | I34: =E34-H34-F34 -> -1 | J34: Sara Mohamed Ali | L34: Farida | M34: 9-6 \ 23-6 \30-6
C35: 5 | E35: =D35+C35 -> 5 | G35: =COUNTIF('Off-Ice Attendence'!$A$1:$J$34,J35) -> 0 | H35: =COUNTIF('June 2026 Attendence'!A:CL,J35) -> 4 | I35: =E35-H35-F35 -> 1 | J35: Massa Ahmed
C36: 5 | E36: =D36+C36 -> 5 | G36: =COUNTIF('Off-Ice Attendence'!$A$1:$J$34,J36) -> 0 | H36: =COUNTIF('June 2026 Attendence'!A:CL,J36) -> 4 | I36: =E36-H36-F36 -> 1 | J36: Malika Ahmed
C37: 0 | E37: =D37+C37 -> 0 | G37: =COUNTIF('Off-Ice Attendence'!$A$1:$J$34,J37) -> 0 | H37: =COUNTIF('June 2026 Attendence'!A:CL,J37) -> 4 | I37: =E37-H37-F37 -> -4 | J37: Rose Mary
C38: 0 | E38: =D38+C38 -> 0 | G38: =COUNTIF('Off-Ice Attendence'!$A$1:$J$34,J38) -> 0 | H38: =COUNTIF('June 2026 Attendence'!A:CL,J38) -> 4 | I38: =E38-H38-F38 -> -4 | J38: Joudy george
C39: 0 | E39: =D39+C39 -> 0 | G39: =COUNTIF('Off-Ice Attendence'!$A$1:$J$34,J39) -> 0 | H39: =COUNTIF('June 2026 Attendence'!A:CL,J39) -> 3 | I39: =E39-H39-F39 -> -3 | J39: Amany
C40: 0 | E40: =D40+C40 -> 0 | G40: =COUNTIF('Off-Ice Attendence'!$A$1:$J$34,J40) -> 0 | H40: =COUNTIF('June 2026 Attendence'!A:CL,J40) -> 2 | I40: =E40-H40-F40 -> -2 | J40: Hajar Abdelwahab
C41: 1 | E41: =D41+C41 -> 1 | G41: =COUNTIF('Off-Ice Attendence'!$A$1:$J$34,J41) -> 0 | H41: =COUNTIF('June 2026 Attendence'!A:CL,J41) -> 1 | I41: =E41-H41-F41 -> 0 | J41: Mariam Ashmawy
...
